Workbook

Sheet Data averaged
A1: Objective | B1: Arch | C1: Prompt | D1: Model | E1: Scenario | F1: Seed | G1: Run | H1: llm_calls | I1: json_generation_failures | J1: llm_missing_or_invalid_actions | K1: charging_station_utilization_rate | L1: elapsed_seconds | M1: steps to first delivery | N1: total deliveries | O1: total steps | P1: deliveries_per_1000_steps | Q1: llm_calls_per_1000_steps | R1: llm_calls_per_delivery | S1: invalid_action_rate | T1: json_failure_rate | U1: Matched prompt pair | V1: Matched Calls-Battery+Shelf pair | W1: Matched three-objective triplet
A2: Battery | B2: Centralized | C2: Natural | D2: llama 1b (3.2) | E2: tiny_balanced_1v1 | H2: =AVERAGEIFS('Data Combined - all-runs'!$H:$H, 'Data Combined - all-runs'!$A:$A, A2,'Data Combined - all-runs'!$B:$B, B2,'Data Combined - all-runs'!$C:$C, C2, 'Data Combined - all-runs'!$D:$D, D2, 'Data Combined - all-runs'!$E:$E, E2) -> 195 | I2: =AVERAGEIFS('Data Combined - all-runs'!$I:$I, 'Data Combined - all-runs'!$A:$A, A2,'Data Combined - all-runs'!$B:$B, B2,'Data Combined - all-runs'!$C:$C, C2, 'Data Combined - all-runs'!$D:$D, D2, 'Data Combined - all-runs'!$E:$E, E2) -> 0 | J2: =AVERAGEIFS('Data Combined - all-runs'!$J:$J, 'Data Combined - all-runs'!$A:$A, A2,'Data Combined - all-runs'!$B:$B, B2,'Data Combined - all-runs'!$C:$C, C2, 'Data Combined - all-runs'!$D:$D, D2, 'Data Combined - all-runs'!$E:$E, E2) -> 7 | K2: =AVERAGEIFS('Data Combined - all-runs'!$K:$K, 'Data Combined - all-runs'!$A:$A, A2,'Data Combined - all-runs'!$B:$B, B2,'Data Combined - all-runs'!$C:$C, C2, 'Data Combined - all-runs'!$D:$D, D2, 'Data Combined - all-runs'!$E:$E, E2) -> 0.03 | L2: =AVERAGEIFS('Data Combined - all-runs'!$L:$L, 'Data Combined - all-runs'!$A:$A, A2,'Data Combined - all-runs'!$B:$B, B2,'Data Combined - all-runs'!$C:$C, C2, 'Data Combined - all-runs'!$D:$D, D2, 'Data Combined - all-runs'!$E:$E, E2) -> 366.24752 | M2: =AVERAGEIFS('Data Combined - all-runs'!$M:$M, 'Data Combined - all-runs'!$A:$A, A2,'Data Combined - all-runs'!$B:$B, B2,'Data Combined - all-runs'!$C:$C, C2, 'Data Combined - all-runs'!$D:$D, D2, 'Data Combined - all-runs'!$E:$E, E2) -> #DIV/0! | N2: =AVERAGEIFS('Data Combined - all-runs'!$N:$N, 'Data Combined - all-runs'!$A:$A, A2,'Data Combined - all-runs'!$B:$B, B2,'Data Combined - all-runs'!$C:$C, C2, 'Data Combined - all-runs'!$D:$D, D2, 'Data Combined - all-runs'!$E:$E, E2) -> 0 | O2: =AVERAGEIFS('Data Combined - all-runs'!$O:$O, 'Data Combined - all-runs'!$A:$A, A2,'Data Combined - all-runs'!$B:$B, B2,'Data Combined - all-runs'!$C:$C, C2, 'Data Combined - all-runs'!$D:$D, D2, 'Data Combined - all-runs'!$E:$E, E2) -> 500 | P2: =AVERAGEIFS('Data Combined - all-runs'!$P:$P, 'Data Combined - all-runs'!$A:$A, A2,'Data Combined - all-runs'!$B:$B, B2,'Data Combined - all-runs'!$C:$C, C2, 'Data Combined - all-runs'!$D:$D, D2, 'Data Combined - all-runs'!$E:$E, E2) -> 0 | Q2: =AVERAGEIFS('Data Combined - all-runs'!$Q:$Q, 'Data Combined - all-runs'!$A:$A, A2,'Data Combined - all-runs'!$B:$B, B2,'Data Combined - all-runs'!$C:$C, C2, 'Data Combined - all-runs'!$D:$D, D2, 'Data Combined - all-runs'!$E:$E, E2) -> 390 | R2: =AVERAGEIFS('Data Combined - all-runs'!$R:$R, 'Data Combined - all-runs'!$A:$A, A2,'Data Combined - all-runs'!$B:$B, B2,'Data Combined - all-runs'!$C:$C, C2, 'Data Combined - all-runs'!$D:$D, D2, 'Data Combined - all-runs'!$E:$E, E2) -> #DIV/0! | S2: =AVERAGEIFS('Data Combined - all-runs'!$S:$S, 'Data Combined - all-runs'!$A:$A, A2,'Data Combined - all-runs'!$B:$B, B2,'Data Combined - all-runs'!$C:$C, C2, 'Data Combined - all-runs'!$D:$D, D2, 'Data Combined - all-runs'!$E:$E, E2) -> 0.035897436 | T2: =AVERAGEIFS('Data Combined - all-runs'!$T:$T, 'Data Combined - all-runs'!$A:$A, A2,'Data Combined - all-runs'!$B:$B, B2,'Data Combined - all-runs'!$C:$C, C2, 'Data Combined - all-runs'!$D:$D, D2, 'Data Combined - all-runs'!$E:$E, E2) -> 0 | U2: =AND( ISNUMBER($H2), SUMPRODUCT( ($A$2:$A$433=$A2)* ($B$2:$B$433=$B2)* ($C$2:$C$433=IF($C2="Json","Natural","Json"))* ($D$2:$D$433=$D2)* ($E$2:$E$433=$E2)* ISNUMBER($H$2:$H$433) )>0 ) -> FALSE | V2: =AND( ISNUMBER($H2), OR($A2="Calls",$A2="Battery + Shelf"), SUMPRODUCT( ($A$2:$A$433=IF($A2="Calls","Battery + Shelf","Calls"))* ($B$2:$B$433=$B2)* ($C$2:$C$433=$C2)* ($D$2:$D$433=$D2)* ($E$2:$E$433=$E2)* ISNUMBER($H$2:$H$433) )>0 ) -> FALSE | W2: =AND( ISNUMBER($H2), OR( $A2="Calls", $A2="Battery + Shelf", $A2="Battery" ), SUMPRODUCT( ($A$2:$A$433="Calls")* ($B$2:$B$433=$B2)* ($C$2:$C$433=$C2)* ($D$2:$D$433=$D2)* ($E$2:$E$433=$E2)* ISNUMBER($H$2:$H$433) )>0, SUMPRODUCT( ($A$2:$A$433="Battery + Shelf")* ($B$2:$B$433=$B2)* ($C$2:$C$433=$C2)* ($D$2:$D$433=$D2)* ($E$2:$E$433=$E2)* ISNUMBER($H$2:$H$433) )>0, SUMPRODUCT( ($A$2:$A$433="Battery")* ($B$2:$B$433=$B2)* ($C$2:$C$433=$C2)* ($D$2:$D$433=$D2)* ($E$2:$E$433=$E2)* ISNUMBER($H$2:$H$433) )>0 ) -> TRUE
A3: Battery | B3: Centralized | C3: Natural | D3: llama 1b (3.2) | E3: small_balanced_2v2 | H3: =AVERAGEIFS('Data Combined - all-runs'!$H:$H, 'Data Combined - all-runs'!$A:$A, A3,'Data Combined - all-runs'!$B:$B, B3,'Data Combined - all-runs'!$C:$C, C3, 'Data Combined - all-runs'!$D:$D, D3, 'Data Combined - all-runs'!$E:$E, E3) -> 370 | I3: =AVERAGEIFS('Data Combined - all-runs'!$I:$I, 'Data Combined - all-runs'!$A:$A, A3,'Data Combined - all-runs'!$B:$B, B3,'Data Combined - all-runs'!$C:$C, C3, 'Data Combined - all-runs'!$D:$D, D3, 'Data Combined - all-runs'!$E:$E, E3) -> 0 | J3: =AVERAGEIFS('Data Combined - all-runs'!$J:$J, 'Data Combined - all-runs'!$A:$A, A3,'Data Combined - all-runs'!$B:$B, B3,'Data Combined - all-runs'!$C:$C, C3, 'Data Combined - all-runs'!$D:$D, D3, 'Data Combined - all-runs'!$E:$E, E3) -> 82 | K3: =AVERAGEIFS('Data Combined - all-runs'!$K:$K, 'Data Combined - all-runs'!$A:$A, A3,'Data Combined - all-runs'!$B:$B, B3,'Data Combined - all-runs'!$C:$C, C3, 'Data Combined - all-runs'!$D:$D, D3, 'Data Combined - all-runs'!$E:$E, E3) -> 0.1735 | L3: =AVERAGEIFS('Data Combined - all-runs'!$L:$L, 'Data Combined - all-runs'!$A:$A, A3,'Data Combined - all-runs'!$B:$B, B3,'Data Combined - all-runs'!$C:$C, C3, 'Data Combined - all-runs'!$D:$D, D3, 'Data Combined - all-runs'!$E:$E, E3) -> 735.98261 | M3: =AVERAGEIFS('Data Combined - all-runs'!$M:$M, 'Data Combined - all-runs'!$A:$A, A3,'Data Combined - all-runs'!$B:$B, B3,'Data Combined - all-runs'!$C:$C, C3, 'Data Combined - all-runs'!$D:$D, D3, 'Data Combined - all-runs'!$E:$E, E3) -> #DIV/0! | N3: =AVERAGEIFS('Data Combined - all-runs'!$N:$N, 'Data Combined - all-runs'!$A:$A, A3,'Data Combined - all-runs'!$B:$B, B3,'Data Combined - all-runs'!$C:$C, C3, 'Data Combined - all-runs'!$D:$D, D3, 'Data Combined - all-runs'!$E:$E, E3) -> 0 | O3: =AVERAGEIFS('Data Combined - all-runs'!$O:$O, 'Data Combined - all-runs'!$A:$A, A3,'Data Combined - all-runs'!$B:$B, B3,'Data Combined - all-runs'!$C:$C, C3, 'Data Combined - all-runs'!$D:$D, D3, 'Data Combined - all-runs'!$E:$E, E3) -> 500 | P3: =AVERAGEIFS('Data Combined - all-runs'!$P:$P, 'Data Combined - all-runs'!$A:$A, A3,'Data Combined - all-runs'!$B:$B, B3,'Data Combined - all-runs'!$C:$C, C3, 'Data Combined - all-runs'!$D:$D, D3, 'Data Combined - all-runs'!$E:$E, E3) -> 0 | Q3: =AVERAGEIFS('Data Combined - all-runs'!$Q:$Q, 'Data Combined - all-runs'!$A:$A, A3,'Data Combined - all-runs'!$B:$B, B3,'Data Combined - all-runs'!$C:$C, C3, 'Data Combined - all-runs'!$D:$D, D3, 'Data Combined - all-runs'!$E:$E, E3) -> 740 | R3: =AVERAGEIFS('Data Combined - all-runs'!$R:$R, 'Data Combined - all-runs'!$A:$A, A3,'Data Combined - all-runs'!$B:$B, B3,'Data Combined - all-runs'!$C:$C, C3, 'Data Combined - all-runs'!$D:$D, D3, 'Data Combined - all-runs'!$E:$E, E3) -> #DIV/0! | S3: =AVERAGEIFS('Data Combined - all-runs'!$S:$S, 'Data Combined - all-runs'!$A:$A, A3,'Data Combined - all-runs'!$B:$B, B3,'Data Combined - all-runs'!$C:$C, C3, 'Data Combined - all-runs'!$D:$D, D3, 'Data Combined - all-runs'!$E:$E, E3) -> 0.22162162 | T3: =AVERAGEIFS('Data Combined - all-runs'!$T:$T, 'Data Combined - all-runs'!$A:$A, A3,'Data Combined - all-runs'!$B:$B, B3,'Data Combined - all-runs'!$C:$C, C3, 'Data Combined - all-runs'!$D:$D, D3, 'Data Combined - all-runs'!$E:$E, E3) -> 0 | U3: =AND( ISNUMBER($H3), SUMPRODUCT( ($A$2:$A$433=$A3)* ($B$2:$B$433=$B3)* ($C$2:$C$433=IF($C3="Json","Natural","Json"))* ($D$2:$D$433=$D3)* ($E$2:$E$433=$E3)* ISNUMBER($H$2:$H$433) )>0 ) -> FALSE | V3: =AND( ISNUMBER($H3), OR($A3="Calls",$A3="Battery + Shelf"), SUMPRODUCT( ($A$2:$A$433=IF($A3="Calls","Battery + Shelf","Calls"))* ($B$2:$B$433=$B3)* ($C$2:$C$433=$C3)* ($D$2:$D$433=$D3)* ($E$2:$E$433=$E3)* ISNUMBER($H$2:$H$433) )>0 ) -> FALSE | W3: =AND( ISNUMBER($H3), OR( $A3="Calls", $A3="Battery + Shelf", $A3="Battery" ), SUMPRODUCT( ($A$2:$A$433="Calls")* ($B$2:$B$433=$B3)* ($C$2:$C$433=$C3)* ($D$2:$D$433=$D3)* ($E$2:$E$433=$E3)* ISNUMBER($H$2:$H$433) )>0, SUMPRODUCT( ($A$2:$A$433="Battery + Shelf")* ($B$2:$B$433=$B3)* ($C$2:$C$433=$C3)* ($D$2:$D$433=$D3)* ($E$2:$E$433=$E3)* ISNUMBER($H$2:$H$433) )>0, SUMPRODUCT( ($A$2:$A$433="Battery")* ($B$2:$B$433=$B3)* ($C$2:$C$433=$C3)* ($D$2:$D$433=$D3)* ($E$2:$E$433=$E3)* ISNUMBER($H$2:$H$433) )>0 ) -> TRUE
A4: Battery | B4: Centralized | C4: Natural | D4: llama 1b (3.2) | E4: small_agv_heavy_4v2 | H4: =AVERAGEIFS('Data Combined - all-runs'!$H:$H, 'Data Combined - all-runs'!$A:$A, A4,'Data Combined - all-runs'!$B:$B, B4,'Data Combined - all-runs'!$C:$C, C4, 'Data Combined - all-runs'!$D:$D, D4, 'Data Combined - all-runs'!$E:$E, E4) -> 752 | I4: =AVERAGEIFS('Data Combined - all-runs'!$I:$I, 'Data Combined - all-runs'!$A:$A, A4,'Data Combined - all-runs'!$B:$B, B4,'Data Combined - all-runs'!$C:$C, C4, 'Data Combined - all-runs'!$D:$D, D4, 'Data Combined - all-runs'!$E:$E, E4) -> 0 | J4: =AVERAGEIFS('Data Combined - all-runs'!$J:$J, 'Data Combined - all-runs'!$A:$A, A4,'Data Combined - all-runs'!$B:$B, B4,'Data Combined - all-runs'!$C:$C, C4, 'Data Combined - all-runs'!$D:$D, D4, 'Data Combined - all-runs'!$E:$E, E4) -> 401 | K4: =AVERAGEIFS('Data Combined - all-runs'!$K:$K, 'Data Combined - all-runs'!$A:$A, A4,'Data Combined - all-runs'!$B:$B, B4,'Data Combined - all-runs'!$C:$C, C4, 'Data Combined - all-runs'!$D:$D, D4, 'Data Combined - all-runs'!$E:$E, E4) -> 0.084530387 | L4: =AVERAGEIFS('Data Combined - all-runs'!$L:$L, 'Data Combined - all-runs'!$A:$A, A4,'Data Combined - all-runs'!$B:$B, B4,'Data Combined - all-runs'!$C:$C, C4, 'Data Combined - all-runs'!$D:$D, D4, 'Data Combined - all-runs'!$E:$E, E4) -> 1644.6051 | M4: =AVERAGEIFS('Data Combined - all-runs'!$M:$M, 'Data Combined - all-runs'!$A:$A, A4,'Data Combined - all-runs'!$B:$B, B4,'Data Combined - all-runs'!$C:$C, C4, 'Data Combined - all-runs'!$D:$D, D4, 'Data Combined - all-runs'!$E:$E, E4) -> 405 | N4: =AVERAGEIFS('Data Combined - all-runs'!$N:$N, 'Data Combined - all-runs'!$A:$A, A4,'Data Combined - all-runs'!$B:$B, B4,'Data Combined - all-runs'!$C:$C, C4, 'Data Combined - all-runs'!$D:$D, D4, 'Data Combined - all-runs'!$E:$E, E4) -> 1 | O4: =AVERAGEIFS('Data Combined - all-runs'!$O:$O, 'Data Combined - all-runs'!$A:$A, A4,'Data Combined - all-runs'!$B:$B, B4,'Data Combined - all-runs'!$C:$C, C4, 'Data Combined - all-runs'!$D:$D, D4, 'Data Combined - all-runs'!$E:$E, E4) -> 905 | P4: =AVERAGEIFS('Data Combined - all-runs'!$P:$P, 'Data Combined - all-runs'!$A:$A, A4,'Data Combined - all-runs'!$B:$B, B4,'Data Combined - all-runs'!$C:$C, C4, 'Data Combined - all-runs'!$D:$D, D4, 'Data Combined - all-runs'!$E:$E, E4) -> 1.1049724 | Q4: =AVERAGEIFS('Data Combined - all-runs'!$Q:$Q, 'Data Combined - all-runs'!$A:$A, A4,'Data Combined - all-runs'!$B:$B, B4,'Data Combined - all-runs'!$C:$C, C4, 'Data Combined - all-runs'!$D:$D, D4, 'Data Combined - all-runs'!$E:$E, E4) -> 830.93923 | R4: =AVERAGEIFS('Data Combined - all-runs'!$R:$R, 'Data Combined - all-runs'!$A:$A, A4,'Data Combined - all-runs'!$B:$B, B4,'Data Combined - all-runs'!$C:$C, C4, 'Data Combined - all-runs'!$D:$D, D4, 'Data Combined - all-runs'!$E:$E, E4) -> 752 | S4: =AVERAGEIFS('Data Combined - all-runs'!$S:$S, 'Data Combined - all-runs'!$A:$A, A4,'Data Combined - all-runs'!$B:$B, B4,'Data Combined - all-runs'!$C:$C, C4, 'Data Combined - all-runs'!$D:$D, D4, 'Data Combined - all-runs'!$E:$E, E4) -> 0.53324468 | T4: =AVERAGEIFS('Data Combined - all-runs'!$T:$T, 'Data Combined - all-runs'!$A:$A, A4,'Data Combined - all-runs'!$B:$B, B4,'Data Combined - all-runs'!$C:$C, C4, 'Data Combined - all-runs'!$D:$D, D4, 'Data Combined - all-runs'!$E:$E, E4) -> 0 | U4: =AND( ISNUMBER($H4), SUMPRODUCT( ($A$2:$A$433=$A4)* ($B$2:$B$433=$B4)* ($C$2:$C$433=IF($C4="Json","Natural","Json"))* ($D$2:$D$433=$D4)* ($E$2:$E$433=$E4)* ISNUMBER($H$2:$H$433) )>0 ) -> FALSE | V4: =AND( ISNUMBER($H4), OR($A4="Calls",$A4="Battery + Shelf"), SUMPRODUCT( ($A$2:$A$433=IF($A4="Calls","Battery + Shelf","Calls"))* ($B$2:$B$433=$B4)* ($C$2:$C$433=$C4)* ($D$2:$D$433=$D4)* ($E$2:$E$433=$E4)* ISNUMBER($H$2:$H$433) )>0 ) -> FALSE | W4: =AND( ISNUMBER($H4), OR( $A4="Calls", $A4="Battery + Shelf", $A4="Battery" ), SUMPRODUCT( ($A$2:$A$433="Calls")* ($B$2:$B$433=$B4)* ($C$2:$C$433=$C4)* ($D$2:$D$433=$D4)* ($E$2:$E$433=$E4)* ISNUMBER($H$2:$H$433) )>0, SUMPRODUCT( ($A$2:$A$433="Battery + Shelf")* ($B$2:$B$433=$B4)* ($C$2:$C$433=$C4)* ($D$2:$D$433=$D4)* ($E$2:$E$433=$E4)* ISNUMBER($H$2:$H$433) )>0, SUMPRODUCT( ($A$2:$A$433="Battery")* ($B$2:$B$433=$B4)* ($C$2:$C$433=$C4)* ($D$2:$D$433=$D4)* ($E$2:$E$433=$E4)* ISNUMBER($H$2:$H$433) )>0 ) -> TRUE
A5: Battery | B5: Centralized | C5: Natural | D5: llama 1b (3.2) | E5: small_picker_heavy_2v4 | H5: =AVERAGEIFS('Data Combined - all-runs'!$H:$H, 'Data Combined - all-runs'!$A:$A, A5,'Data Combined - all-runs'!$B:$B, B5,'Data Combined - all-runs'!$C:$C, C5, 'Data Combined - all-runs'!$D:$D, D5, 'Data Combined - all-runs'!$E:$E, E5) -> 418 | I5: =AVERAGEIFS('Data Combined - all-runs'!$I:$I, 'Data Combined - all-runs'!$A:$A, A5,'Data Combined - all-runs'!$B:$B, B5,'Data Combined - all-runs'!$C:$C, C5, 'Data Combined - all-runs'!$D:$D, D5, 'Data Combined - all-runs'!$E:$E, E5) -> 0 | J5: =AVERAGEIFS('Data Combined - all-runs'!$J:$J, 'Data Combined - all-runs'!$A:$A, A5,'Data Combined - all-runs'!$B:$B, B5,'Data Combined - all-runs'!$C:$C, C5, 'Data Combined - all-runs'!$D:$D, D5, 'Data Combined - all-runs'!$E:$E, E5) -> 124 | K5: =AVERAGEIFS('Data Combined - all-runs'!$K:$K, 'Data Combined - all-runs'!$A:$A, A5,'Data Combined - all-runs'!$B:$B, B5,'Data Combined - all-runs'!$C:$C, C5, 'Data Combined - all-runs'!$D:$D, D5, 'Data Combined - all-runs'!$E:$E, E5) -> 0.15733333 | L5: =AVERAGEIFS('Data Combined - all-runs'!$L:$L, 'Data Combined - all-runs'!$A:$A, A5,'Data Combined - all-runs'!$B:$B, B5,'Data Combined - all-runs'!$C:$C, C5, 'Data Combined - all-runs'!$D:$D, D5, 'Data Combined - all-runs'!$E:$E, E5) -> 908.72897 | M5: =AVERAGEIFS('Data Combined - all-runs'!$M:$M, 'Data Combined - all-runs'!$A:$A, A5,'Data Combined - all-runs'!$B:$B, B5,'Data Combined - all-runs'!$C:$C, C5, 'Data Combined - all-runs'!$D:$D, D5, 'Data Combined - all-runs'!$E:$E, E5) -> #DIV/0! | N5: =AVERAGEIFS('Data Combined - all-runs'!$N:$N, 'Data Combined - all-runs'!$A:$A, A5,'Data Combined - all-runs'!$B:$B, B5,'Data Combined - all-runs'!$C:$C, C5, 'Data Combined - all-runs'!$D:$D, D5, 'Data Combined - all-runs'!$E:$E, E5) -> 0 | O5: =AVERAGEIFS('Data Combined - all-runs'!$O:$O, 'Data Combined - all-runs'!$A:$A, A5,'Data Combined - all-runs'!$B:$B, B5,'Data Combined - all-runs'!$C:$C, C5, 'Data Combined - all-runs'!$D:$D, D5, 'Data Combined - all-runs'!$E:$E, E5) -> 500 | P5: =AVERAGEIFS('Data Combined - all-runs'!$P:$P, 'Data Combined - all-runs'!$A:$A, A5,'Data Combined - all-runs'!$B:$B, B5,'Data Combined - all-runs'!$C:$C, C5, 'Data Combined - all-runs'!$D:$D, D5, 'Data Combined - all-runs'!$E:$E, E5) -> 0 | Q5: =AVERAGEIFS('Data Combined - all-runs'!$Q:$Q, 'Data Combined - all-runs'!$A:$A, A5,'Data Combined - all-runs'!$B:$B, B5,'Data Combined - all-runs'!$C:$C, C5, 'Data Combined - all-runs'!$D:$D, D5, 'Data Combined - all-runs'!$E:$E, E5) -> 836 | R5: =AVERAGEIFS('Data Combined - all-runs'!$R:$R, 'Data Combined - all-runs'!$A:$A, A5,'Data Combined - all-runs'!$B:$B, B5,'Data Combined - all-runs'!$C:$C, C5, 'Data Combined - all-runs'!$D:$D, D5, 'Data Combined - all-runs'!$E:$E, E5) -> #DIV/0! | S5: =AVERAGEIFS('Data Combined - all-runs'!$S:$S, 'Data Combined - all-runs'!$A:$A, A5,'Data Combined - all-runs'!$B:$B, B5,'Data Combined - all-runs'!$C:$C, C5, 'Data Combined - all-runs'!$D:$D, D5, 'Data Combined - all-runs'!$E:$E, E5) -> 0.29665072 | T5: =AVERAGEIFS('Data Combined - all-runs'!$T:$T, 'Data Combined - all-runs'!$A:$A, A5,'Data Combined - all-runs'!$B:$B, B5,'Data Combined - all-runs'!$C:$C, C5, 'Data Combined - all-runs'!$D:$D, D5, 'Data Combined - all-runs'!$E:$E, E5) -> 0 | U5: =AND( ISNUMBER($H5), SUMPRODUCT( ($A$2:$A$433=$A5)* ($B$2:$B$433=$B5)* ($C$2:$C$433=IF($C5="Json","Natural","Json"))* ($D$2:$D$433=$D5)* ($E$2:$E$433=$E5)* ISNUMBER($H$2:$H$433) )>0 ) -> FALSE | V5: =AND( ISNUMBER($H5), OR($A5="Calls",$A5="Battery + Shelf"), SUMPRODUCT( ($A$2:$A$433=IF($A5="Calls","Battery + Shelf","Calls"))* ($B$2:$B$433=$B5)* ($C$2:$C$433=$C5)* ($D$2:$D$433=$D5)* ($E$2:$E$433=$E5)* ISNUMBER($H$2:$H$433) )>0 ) -> FALSE | W5: =AND( ISNUMBER($H5), OR( $A5="Calls", $A5="Battery + Shelf", $A5="Battery" ), SUMPRODUCT( ($A$2:$A$433="Calls")* ($B$2:$B$433=$B5)* ($C$2:$C$433=$C5)* ($D$2:$D$433=$D5)* ($E$2:$E$433=$E5)* ISNUMBER($H$2:$H$433) )>0, SUMPRODUCT( ($A$2:$A$433="Battery + Shelf")* ($B$2:$B$433=$B5)* ($C$2:$C$433=$C5)* ($D$2:$D$433=$D5)* ($E$2:$E$433=$E5)* ISNUMBER($H$2:$H$433) )>0, SUMPRODUCT( ($A$2:$A$433="Battery")* ($B$2:$B$433=$B5)* ($C$2:$C$433=$C5)* ($D$2:$D$433=$D5)* ($E$2:$E$433=$E5)* ISNUMBER($H$2:$H$433) )>0 ) -> TRUE
A6: Battery | B6: Centralized | C6: Natural | D6: llama 1b (3.2) | E6: medium_balanced_4v4 | H6: =AVERAGEIFS('Data Combined - all-runs'!$H:$H, 'Data Combined - all-runs'!$A:$A, A6,'Data Combined - all-runs'!$B:$B, B6,'Data Combined - all-runs'!$C:$C, C6, 'Data Combined - all-runs'!$D:$D, D6, 'Data Combined - all-runs'!$E:$E, E6) -> 628 | I6: =AVERAGEIFS('Data Combined - all-runs'!$I:$I, 'Data Combined - all-runs'!$A:$A, A6,'Data Combined - all-runs'!$B:$B, B6,'Data Combined - all-runs'!$C:$C, C6, 'Data Combined - all-runs'!$D:$D, D6, 'Data Combined - all-runs'!$E:$E, E6) -> 0 | J6: =AVERAGEIFS('Data Combined - all-runs'!$J:$J, 'Data Combined - all-runs'!$A:$A, A6,'Data Combined - all-runs'!$B:$B, B6,'Data Combined - all-runs'!$C:$C, C6, 'Data Combined - all-runs'!$D:$D, D6, 'Data Combined - all-runs'!$E:$E, E6) -> 302 | K6: =AVERAGEIFS('Data Combined - all-runs'!$K:$K, 'Data Combined - all-runs'!$A:$A, A6,'Data Combined - all-runs'!$B:$B, B6,'Data Combined - all-runs'!$C:$C, C6, 'Data Combined - all-runs'!$D:$D, D6, 'Data Combined - all-runs'!$E:$E, E6) -> 0.12220149 | L6: =AVERAGEIFS('Data Combined - all-runs'!$L:$L, 'Data Combined - all-runs'!$A:$A, A6,'Data Combined - all-runs'!$B:$B, B6,'Data Combined - all-runs'!$C:$C, C6, 'Data Combined - all-runs'!$D:$D, D6, 'Data Combined - all-runs'!$E:$E, E6) -> 1656.1751 | M6: =AVERAGEIFS('Data Combined - all-runs'!$M:$M, 'Data Combined - all-runs'!$A:$A, A6,'Data Combined - all-runs'!$B:$B, B6,'Data Combined - all-runs'!$C:$C, C6, 'Data Combined - all-runs'!$D:$D, D6, 'Data Combined - all-runs'!$E:$E, E6) -> 170 | N6: =AVERAGEIFS('Data Combined - all-runs'!$N:$N, 'Data Combined - all-runs'!$A:$A, A6,'Data Combined - all-runs'!$B:$B, B6,'Data Combined - all-runs'!$C:$C, C6, 'Data Combined - all-runs'!$D:$D, D6, 'Data Combined - all-runs'!$E:$E, E6) -> 1 | O6: =AVERAGEIFS('Data Combined - all-runs'!$O:$O, 'Data Combined - all-runs'!$A:$A, A6,'Data Combined - all-runs'!$B:$B, B6,'Data Combined - all-runs'!$C:$C, C6, 'Data Combined - all-runs'!$D:$D, D6, 'Data Combined - all-runs'!$E:$E, E6) -> 670 | P6: =AVERAGEIFS('Data Combined - all-runs'!$P:$P, 'Data Combined - all-runs'!$A:$A, A6,'Data Combined - all-runs'!$B:$B, B6,'Data Combined - all-runs'!$C:$C, C6, 'Data Combined - all-runs'!$D:$D, D6, 'Data Combined - all-runs'!$E:$E, E6) -> 1.4925373 | Q6: =AVERAGEIFS('Data Combined - all-runs'!$Q:$Q, 'Data Combined - all-runs'!$A:$A, A6,'Data Combined - all-runs'!$B:$B, B6,'Data Combined - all-runs'!$C:$C, C6, 'Data Combined - all-runs'!$D:$D, D6, 'Data Combined - all-runs'!$E:$E, E6) -> 937.31343 | R6: =AVERAGEIFS('Data Combined - all-runs'!$R:$R, 'Data Combined - all-runs'!$A:$A, A6,'Data Combined - all-runs'!$B:$B, B6,'Data Combined - all-runs'!$C:$C, C6, 'Data Combined - all-runs'!$D:$D, D6, 'Data Combined - all-runs'!$E:$E, E6) -> 628 | S6: =AVERAGEIFS('Data Combined - all-runs'!$S:$S, 'Data Combined - all-runs'!$A:$A, A6,'Data Combined - all-runs'!$B:$B, B6,'Data Combined - all-runs'!$C:$C, C6, 'Data Combined - all-runs'!$D:$D, D6, 'Data Combined - all-runs'!$E:$E, E6) -> 0.48089172 | T6: =AVERAGEIFS('Data Combined - all-runs'!$T:$T, 'Data Combined - all-runs'!$A:$A, A6,'Data Combined - all-runs'!$B:$B, B6,'Data Combined - all-runs'!$C:$C, C6, 'Data Combined - all-runs'!$D:$D, D6, 'Data Combined - all-runs'!$E:$E, E6) -> 0 | U6: =AND( ISNUMBER($H6), SUMPRODUCT( ($A$2:$A$433=$A6)* ($B$2:$B$433=$B6)* ($C$2:$C$433=IF($C6="Json","Natural","Json"))* ($D$2:$D$433=$D6)* ($E$2:$E$433=$E6)* ISNUMBER($H$2:$H$433) )>0 ) -> FALSE | V6: =AND( ISNUMBER($H6), OR($A6="Calls",$A6="Battery + Shelf"), SUMPRODUCT( ($A$2:$A$433=IF($A6="Calls","Battery + Shelf","Calls"))* ($B$2:$B$433=$B6)* ($C$2:$C$433=$C6)* ($D$2:$D$433=$D6)* ($E$2:$E$433=$E6)* ISNUMBER($H$2:$H$433) )>0 ) -> FALSE | W6: =AND( ISNUMBER($H6), OR( $A6="Calls", $A6="Battery + Shelf", $A6="Battery" ), SUMPRODUCT( ($A$2:$A$433="Calls")* ($B$2:$B$433=$B6)* ($C$2:$C$433=$C6)* ($D$2:$D$433=$D6)* ($E$2:$E$433=$E6)* ISNUMBER($H$2:$H$433) )>0, SUMPRODUCT( ($A$2:$A$433="Battery + Shelf")* ($B$2:$B$433=$B6)* ($C$2:$C$433=$C6)* ($D$2:$D$433=$D6)* ($E$2:$E$433=$E6)* ISNUMBER($H$2:$H$433) )>0, SUMPRODUCT( ($A$2:$A$433="Battery")* ($B$2:$B$433=$B6)* ($C$2:$C$433=$C6)* ($D$2:$D$433=$D6)* ($E$2:$E$433=$E6)* ISNUMBER($H$2:$H$433) )>0 ) -> TRUE
A7: Battery | B7: Centralized | C7: Natural | D7: llama 1b (3.2) | E7: medium_agv_heavy_6v2 | H7: =AVERAGEIFS('Data Combined - all-runs'!$H:$H, 'Data Combined - all-runs'!$A:$A, A7,'Data Combined - all-runs'!$B:$B, B7,'Data Combined - all-runs'!$C:$C, C7, 'Data Combined - all-runs'!$D:$D, D7, 'Data Combined - all-runs'!$E:$E, E7) -> 819 | I7: =AVERAGEIFS('Data Combined - all-runs'!$I:$I, 'Data Combined - all-runs'!$A:$A, A7,'Data Combined - all-runs'!$B:$B, B7,'Data Combined - all-runs'!$C:$C, C7, 'Data Combined - all-runs'!$D:$D, D7, 'Data Combined - all-runs'!$E:$E, E7) -> 0 | J7: =AVERAGEIFS('Data Combined - all-runs'!$J:$J, 'Data Combined - all-runs'!$A:$A, A7,'Data Combined - all-runs'!$B:$B, B7,'Data Combined - all-runs'!$C:$C, C7, 'Data Combined - all-runs'!$D:$D, D7, 'Data Combined - all-runs'!$E:$E, E7) -> 649 | K7: =AVERAGEIFS('Data Combined - all-runs'!$K:$K, 'Data Combined - all-runs'!$A:$A, A7,'Data Combined - all-runs'!$B:$B, B7,'Data Combined - all-runs'!$C:$C, C7, 'Data Combined - all-runs'!$D:$D, D7, 'Data Combined - all-runs'!$E:$E, E7) -> 0.091561424 | L7: =AVERAGEIFS('Data Combined - all-runs'!$L:$L, 'Data Combined - all-runs'!$A:$A, A7,'Data Combined - all-runs'!$B:$B, B7,'Data Combined - all-runs'!$C:$C, C7, 'Data Combined - all-runs'!$D:$D, D7, 'Data Combined - all-runs'!$E:$E, E7) -> 1986.8931 | M7: =AVERAGEIFS('Data Combined - all-runs'!$M:$M, 'Data Combined - all-runs'!$A:$A, A7,'Data Combined - all-runs'!$B:$B, B7,'Data Combined - all-runs'!$C:$C, C7, 'Data Combined - all-runs'!$D:$D, D7, 'Data Combined - all-runs'!$E:$E, E7) -> 312 | N7: =AVERAGEIFS('Data Combined - all-runs'!$N:$N, 'Data Combined - all-runs'!$A:$A, A7,'Data Combined - all-runs'!$B:$B, B7,'Data Combined - all-runs'!$C:$C, C7, 'Data Combined - all-runs'!$D:$D, D7, 'Data Combined - all-runs'!$E:$E, E7) -> 2 | O7: =AVERAGEIFS('Data Combined - all-runs'!$O:$O, 'Data Combined - all-runs'!$A:$A, A7,'Data Combined - all-runs'!$B:$B, B7,'Data Combined - all-runs'!$C:$C, C7, 'Data Combined - all-runs'!$D:$D, D7, 'Data Combined - all-runs'!$E:$E, E7) -> 871 | P7: =AVERAGEIFS('Data Combined - all-runs'!$P:$P, 'Data Combined - all-runs'!$A:$A, A7,'Data Combined - all-runs'!$B:$B, B7,'Data Combined - all-runs'!$C:$C, C7, 'Data Combined - all-runs'!$D:$D, D7, 'Data Combined - all-runs'!$E:$E, E7) -> 2.2962113 | Q7: =AVERAGEIFS('Data Combined - all-runs'!$Q:$Q, 'Data Combined - all-runs'!$A:$A, A7,'Data Combined - all-runs'!$B:$B, B7,'Data Combined - all-runs'!$C:$C, C7, 'Data Combined - all-runs'!$D:$D, D7, 'Data Combined - all-runs'!$E:$E, E7) -> 940.29851 | R7: =AVERAGEIFS('Data Combined - all-runs'!$R:$R, 'Data Combined - all-runs'!$A:$A, A7,'Data Combined - all-runs'!$B:$B, B7,'Data Combined - all-runs'!$C:$C, C7, 'Data Combined - all-runs'!$D:$D, D7, 'Data Combined - all-runs'!$E:$E, E7) -> 409.5 | S7: =AVERAGEIFS('Data Combined - all-runs'!$S:$S, 'Data Combined - all-runs'!$A:$A, A7,'Data Combined - all-runs'!$B:$B, B7,'Data Combined - all-runs'!$C:$C, C7, 'Data Combined - all-runs'!$D:$D, D7, 'Data Combined - all-runs'!$E:$E, E7) -> 0.79242979 | T7: =AVERAGEIFS('Data Combined - all-runs'!$T:$T, 'Data Combined - all-runs'!$A:$A, A7,'Data Combined - all-runs'!$B:$B, B7,'Data Combined - all-runs'!$C:$C, C7, 'Data Combined - all-runs'!$D:$D, D7, 'Data Combined - all-runs'!$E:$E, E7) -> 0 | U7: =AND( ISNUMBER($H7), SUMPRODUCT( ($A$2:$A$433=$A7)* ($B$2:$B$433=$B7)* ($C$2:$C$433=IF($C7="Json","Natural","Json"))* ($D$2:$D$433=$D7)* ($E$2:$E$433=$E7)* ISNUMBER($H$2:$H$433) )>0 ) -> FALSE | V7: =AND( ISNUMBER($H7), OR($A7="Calls",$A7="Battery + Shelf"), SUMPRODUCT( ($A$2:$A$433=IF($A7="Calls","Battery + Shelf","Calls"))* ($B$2:$B$433=$B7)* ($C$2:$C$433=$C7)* ($D$2:$D$433=$D7)* ($E$2:$E$433=$E7)* ISNUMBER($H$2:$H$433) )>0 ) -> FALSE | W7: =AND( ISNUMBER($H7), OR( $A7="Calls", $A7="Battery + Shelf", $A7="Battery" ), SUMPRODUCT( ($A$2:$A$433="Calls")* ($B$2:$B$433=$B7)* ($C$2:$C$433=$C7)* ($D$2:$D$433=$D7)* ($E$2:$E$433=$E7)* ISNUMBER($H$2:$H$433) )>0, SUMPRODUCT( ($A$2:$A$433="Battery + Shelf")* ($B$2:$B$433=$B7)* ($C$2:$C$433=$C7)* ($D$2:$D$433=$D7)* ($E$2:$E$433=$E7)* ISNUMBER($H$2:$H$433) )>0, SUMPRODUCT( ($A$2:$A$433="Battery")* ($B$2:$B$433=$B7)* ($C$2:$C$433=$C7)* ($D$2:$D$433=$D7)* ($E$2:$E$433=$E7)* ISNUMBER($H$2:$H$433) )>0 ) -> TRUE
A8: Battery | B8: Centralized | C8: Natural | D8: llama 3b (3.2) | E8: tiny_balanced_1v1 | H8: =AVERAGEIFS('Data Combined - all-runs'!$H:$H, 'Data Combined - all-runs'!$A:$A, A8,'Data Combined - all-runs'!$B:$B, B8,'Data Combined - all-runs'!$C:$C, C8, 'Data Combined - all-runs'!$D:$D, D8, 'Data Combined - all-runs'!$E:$E, E8) -> 404.5 | I8: =AVERAGEIFS('Data Combined - all-runs'!$I:$I, 'Data Combined - all-runs'!$A:$A, A8,'Data Combined - all-runs'!$B:$B, B8,'Data Combined - all-runs'!$C:$C, C8, 'Data Combined - all-runs'!$D:$D, D8, 'Data Combined - all-runs'!$E:$E, E8) -> 0 | J8: =AVERAGEIFS('Data Combined - all-runs'!$J:$J, 'Data Combined - all-runs'!$A:$A, A8,'Data Combined - all-runs'!$B:$B, B8,'Data Combined - all-runs'!$C:$C, C8, 'Data Combined - all-runs'!$D:$D, D8, 'Data Combined - all-runs'!$E:$E, E8) -> 48 | K8: =AVERAGEIFS('Data Combined - all-runs'!$K:$K, 'Data Combined - all-runs'!$A:$A, A8,'Data Combined - all-runs'!$B:$B, B8,'Data Combined - all-runs'!$C:$C, C8, 'Data Combined - all-runs'!$D:$D, D8, 'Data Combined - all-runs'!$E:$E, E8) -> 0.1312754 | L8: =AVERAGEIFS('Data Combined - all-runs'!$L:$L, 'Data Combined - all-runs'!$A:$A, A8,'Data Combined - all-runs'!$B:$B, B8,'Data Combined - all-runs'!$C:$C, C8, 'Data Combined - all-runs'!$D:$D, D8, 'Data Combined - all-runs'!$E:$E, E8) -> 7436.2959 | M8: =AVERAGEIFS('Data Combined - all-runs'!$M:$M, 'Data Combined - all-runs'!$A:$A, A8,'Data Combined - all-runs'!$B:$B, B8,'Data Combined - all-runs'!$C:$C, C8, 'Data Combined - all-runs'!$D:$D, D8, 'Data Combined - all-runs'!$E:$E, E8) -> 317 | N8: =AVERAGEIFS('Data Combined - all-runs'!$N:$N, 'Data Combined - all-runs'!$A:$A, A8,'Data Combined - all-runs'!$B:$B, B8,'Data Combined - all-runs'!$C:$C, C8, 'Data Combined - all-runs'!$D:$D, D8, 'Data Combined - all-runs'!$E:$E, E8) -> 0.5 | O8: =AVERAGEIFS('Data Combined - all-runs'!$O:$O, 'Data Combined - all-runs'!$A:$A, A8,'Data Combined - all-runs'!$B:$B, B8,'Data Combined - all-runs'!$C:$C, C8, 'Data Combined - all-runs'!$D:$D, D8, 'Data Combined - all-runs'!$E:$E, E8) -> 658.5 | P8: =AVERAGEIFS('Data Combined - all-runs'!$P:$P, 'Data Combined - all-runs'!$A:$A, A8,'Data Combined - all-runs'!$B:$B, B8,'Data Combined - all-runs'!$C:$C, C8, 'Data Combined - all-runs'!$D:$D, D8, 'Data Combined - all-runs'!$E:$E, E8) -> 0.6119951 | Q8: =AVERAGEIFS('Data Combined - all-runs'!$Q:$Q, 'Data Combined - all-runs'!$A:$A, A8,'Data Combined - all-runs'!$B:$B, B8,'Data Combined - all-runs'!$C:$C, C8, 'Data Combined - all-runs'!$D:$D, D8, 'Data Combined - all-runs'!$E:$E, E8) -> 634.7858 | R8: =AVERAGEIFS('Data Combined - all-runs'!$R:$R, 'Data Combined - all-runs'!$A:$A, A8,'Data Combined - all-runs'!$B:$B, B8,'Data Combined - all-runs'!$C:$C, C8, 'Data Combined - all-runs'!$D:$D, D8, 'Data Combined - all-runs'!$E:$E, E8) -> 449 | S8: =AVERAGEIFS('Data Combined - all-runs'!$S:$S, 'Data Combined - all-runs'!$A:$A, A8,'Data Combined - all-runs'!$B:$B, B8,'Data Combined - all-runs'!$C:$C, C8, 'Data Combined - all-runs'!$D:$D, D8, 'Data Combined - all-runs'!$E:$E, E8) -> 0.12397303 | T8: =AVERAGEIFS('Data Combined - all-runs'!$T:$T, 'Data Combined - all-runs'!$A:$A, A8,'Data Combined - all-runs'!$B:$B, B8,'Data Combined - all-runs'!$C:$C, C8, 'Data Combined - all-runs'!$D:$D, D8, 'Data Combined - all-runs'!$E:$E, E8) -> 0 | U8: =AND( ISNUMBER($H8), SUMPRODUCT( ($A$2:$A$433=$A8)* ($B$2:$B$433=$B8)* ($C$2:$C$433=IF($C8="Json","Natural","Json"))* ($D$2:$D$433=$D8)* ($E$2:$E$433=$E8)* ISNUMBER($H$2:$H$433) )>0 ) -> FALSE | V8: =AND( ISNUMBER($H8), OR($A8="Calls",$A8="Battery + Shelf"), SUMPRODUCT( ($A$2:$A$433=IF($A8="Calls","Battery + Shelf","Calls"))* ($B$2:$B$433=$B8)* ($C$2:$C$433=$C8)* ($D$2:$D$433=$D8)* ($E$2:$E$433=$E8)* ISNUMBER($H$2:$H$433) )>0 ) -> FALSE | W8: =AND( ISNUMBER($H8), OR( $A8="Calls", $A8="Battery + Shelf", $A8="Battery" ), SUMPRODUCT( ($A$2:$A$433="Calls")* ($B$2:$B$433=$B8)* ($C$2:$C$433=$C8)* ($D$2:$D$433=$D8)* ($E$2:$E$433=$E8)* ISNUMBER($H$2:$H$433) )>0, SUMPRODUCT( ($A$2:$A$433="Battery + Shelf")* ($B$2:$B$433=$B8)* ($C$2:$C$433=$C8)* ($D$2:$D$433=$D8)* ($E$2:$E$433=$E8)* ISNUMBER($H$2:$H$433) )>0, SUMPRODUCT( ($A$2:$A$433="Battery")* ($B$2:$B$433=$B8)* ($C$2:$C$433=$C8)* ($D$2:$D$433=$D8)* ($E$2:$E$433=$E8)* ISNUMBER($H$2:$H$433) )>0 ) -> TRUE
A9: Battery | B9: Centralized | C9: Natural | D9: llama 3b (3.2) | E9: small_balanced_2v2 | H9: =AVERAGEIFS('Data Combined - all-runs'!$H:$H, 'Data Combined - all-runs'!$A:$A, A9,'Data Combined - all-runs'!$B:$B, B9,'Data Combined - all-runs'!$C:$C, C9, 'Data Combined - all-runs'!$D:$D, D9, 'Data Combined - all-runs'!$E:$E, E9) -> 617 | I9: =AVERAGEIFS('Data Combined - all-runs'!$I:$I, 'Data Combined - all-runs'!$A:$A, A9,'Data Combined - all-runs'!$B:$B, B9,'Data Combined - all-runs'!$C:$C, C9, 'Data Combined - all-runs'!$D:$D, D9, 'Data Combined - all-runs'!$E:$E, E9) -> 0 | J9: =AVERAGEIFS('Data Combined - all-runs'!$J:$J, 'Data Combined - all-runs'!$A:$A, A9,'Data Combined - all-runs'!$B:$B, B9,'Data Combined - all-runs'!$C:$C, C9, 'Data Combined - all-runs'!$D:$D, D9, 'Data Combined - all-runs'!$E:$E, E9) -> 597 | K9: =AVERAGEIFS('Data Combined - all-runs'!$K:$K, 'Data Combined - all-runs'!$A:$A, A9,'Data Combined - all-runs'!$B:$B, B9,'Data Combined - all-runs'!$C:$C, C9, 'Data Combined - all-runs'!$D:$D, D9, 'Data Combined - all-runs'!$E:$E, E9) -> 0.20883413 | L9: =AVERAGEIFS('Data Combined - all-runs'!$L:$L, 'Data Combined - all-runs'!$A:$A, A9,'Data Combined - all-runs'!$B:$B, B9,'Data Combined - all-runs'!$C:$C, C9, 'Data Combined - all-runs'!$D:$D, D9, 'Data Combined - all-runs'!$E:$E, E9) -> 3628.4922 | M9: =AVERAGEIFS('Data Combined - all-runs'!$M:$M, 'Data Combined - all-runs'!$A:$A, A9,'Data Combined - all-runs'!$B:$B, B9,'Data Combined - all-runs'!$C:$C, C9, 'Data Combined - all-runs'!$D:$D, D9, 'Data Combined - all-runs'!$E:$E, E9) -> 322 | N9: =AVERAGEIFS('Data Combined - all-runs'!$N:$N, 'Data Combined - all-runs'!$A:$A, A9,'Data Combined - all-runs'!$B:$B, B9,'Data Combined - all-runs'!$C:$C, C9, 'Data Combined - all-runs'!$D:$D, D9, 'Data Combined - all-runs'!$E:$E, E9) -> 2 | O9: =AVERAGEIFS('Data Combined - all-runs'!$O:$O, 'Data Combined - all-runs'!$A:$A, A9,'Data Combined - all-runs'!$B:$B, B9,'Data Combined - all-runs'!$C:$C, C9, 'Data Combined - all-runs'!$D:$D, D9, 'Data Combined - all-runs'!$E:$E, E9) -> 832 | P9: =AVERAGEIFS('Data Combined - all-runs'!$P:$P, 'Data Combined - all-runs'!$A:$A, A9,'Data Combined - all-runs'!$B:$B, B9,'Data Combined - all-runs'!$C:$C, C9, 'Data Combined - all-runs'!$D:$D, D9, 'Data Combined - all-runs'!$E:$E, E9) -> 2.4038462 | Q9: =AVERAGEIFS('Data Combined - all-runs'!$Q:$Q, 'Data Combined - all-runs'!$A:$A, A9,'Data Combined - all-runs'!$B:$B, B9,'Data Combined - all-runs'!$C:$C, C9, 'Data Combined - all-runs'!$D:$D, D9, 'Data Combined - all-runs'!$E:$E, E9) -> 741.58654 | R9: =AVERAGEIFS('Data Combined - all-runs'!$R:$R, 'Data Combined - all-runs'!$A:$A, A9,'Data Combined - all-runs'!$B:$B, B9,'Data Combined - all-runs'!$C:$C, C9, 'Data Combined - all-runs'!$D:$D, D9, 'Data Combined - all-runs'!$E:$E, E9) -> 308.5 | S9: =AVERAGEIFS('Data Combined - all-runs'!$S:$S, 'Data Combined - all-runs'!$A:$A, A9,'Data Combined - all-runs'!$B:$B, B9,'Data Combined - all-runs'!$C:$C, C9, 'Data Combined - all-runs'!$D:$D, D9, 'Data Combined - all-runs'!$E:$E, E9) -> 0.96758509 | T9: =AVERAGEIFS('Data Combined - all-runs'!$T:$T, 'Data Combined - all-runs'!$A:$A, A9,'Data Combined - all-runs'!$B:$B, B9,'Data Combined - all-runs'!$C:$C, C9, 'Data Combined - all-runs'!$D:$D, D9, 'Data Combined - all-runs'!$E:$E, E9) -> 0 | U9: =AND( ISNUMBER($H9), SUMPRODUCT( ($A$2:$A$433=$A9)* ($B$2:$B$433=$B9)* ($C$2:$C$433=IF($C9="Json","Natural","Json"))* ($D$2:$D$433=$D9)* ($E$2:$E$433=$E9)* ISNUMBER($H$2:$H$433) )>0 ) -> FALSE | V9: =AND( ISNUMBER($H9), OR($A9="Calls",$A9="Battery + Shelf"), SUMPRODUCT( ($A$2:$A$433=IF($A9="Calls","Battery + Shelf","Calls"))* ($B$2:$B$433=$B9)* ($C$2:$C$433=$C9)* ($D$2:$D$433=$D9)* ($E$2:$E$433=$E9)* ISNUMBER($H$2:$H$433) )>0 ) -> FALSE | W9: =AND( ISNUMBER($H9), OR( $A9="Calls", $A9="Battery + Shelf", $A9="Battery" ), SUMPRODUCT( ($A$2:$A$433="Calls")* ($B$2:$B$433=$B9)* ($C$2:$C$433=$C9)* ($D$2:$D$433=$D9)* ($E$2:$E$433=$E9)* ISNUMBER($H$2:$H$433) )>0, SUMPRODUCT( ($A$2:$A$433="Battery + Shelf")* ($B$2:$B$433=$B9)* ($C$2:$C$433=$C9)* ($D$2:$D$433=$D9)* ($E$2:$E$433=$E9)* ISNUMBER($H$2:$H$433) )>0, SUMPRODUCT( ($A$2:$A$433="Battery")* ($B$2:$B$433=$B9)* ($C$2:$C$433=$C9)* ($D$2:$D$433=$D9)* ($E$2:$E$433=$E9)* ISNUMBER($H$2:$H$433) )>0 ) -> TRUE
A10: Battery | B10: Centralized | C10: Natural | D10: llama 3b (3.2) | E10: small_agv_heavy_4v2 | H10: =AVERAGEIFS('Data Combined - all-runs'!$H:$H, 'Data Combined - all-runs'!$A:$A, A10,'Data Combined - all-runs'!$B:$B, B10,'Data Combined - all-runs'!$C:$C, C10, 'Data Combined - all-runs'!$D:$D, D10, 'Data Combined - all-runs'!$E:$E, E10) -> 1492 | I10: =AVERAGEIFS('Data Combined - all-runs'!$I:$I, 'Data Combined - all-runs'!$A:$A, A10,'Data Combined - all-runs'!$B:$B, B10,'Data Combined - all-runs'!$C:$C, C10, 'Data Combined - all-runs'!$D:$D, D10, 'Data Combined - all-runs'!$E:$E, E10) -> 0 | J10: =AVERAGEIFS('Data Combined - all-runs'!$J:$J, 'Data Combined - all-runs'!$A:$A, A10,'Data Combined - all-runs'!$B:$B, B10,'Data Combined - all-runs'!$C:$C, C10, 'Data Combined - all-runs'!$D:$D, D10, 'Data Combined - all-runs'!$E:$E, E10) -> 350 | K10: =AVERAGEIFS('Data Combined - all-runs'!$K:$K, 'Data Combined - all-runs'!$A:$A, A10,'Data Combined - all-runs'!$B:$B, B10,'Data Combined - all-runs'!$C:$C, C10, 'Data Combined - all-runs'!$D:$D, D10, 'Data Combined - all-runs'!$E:$E, E10) -> 0.14158249 | L10: =AVERAGEIFS('Data Combined - all-runs'!$L:$L, 'Data Combined - all-runs'!$A:$A, A10,'Data Combined - all-runs'!$B:$B, B10,'Data Combined - all-runs'!$C:$C, C10, 'Data Combined - all-runs'!$D:$D, D10, 'Data Combined - all-runs'!$E:$E, E10) -> 9455.9374 | M10: =AVERAGEIFS('Data Combined - all-runs'!$M:$M, 'Data Combined - all-runs'!$A:$A, A10,'Data Combined - all-runs'!$B:$B, B10,'Data Combined - all-runs'!$C:$C, C10, 'Data Combined - all-runs'!$D:$D, D10, 'Data Combined - all-runs'!$E:$E, E10) -> 130 | N10: =AVERAGEIFS('Data Combined - all-runs'!$N:$N, 'Data Combined - all-runs'!$A:$A, A10,'Data Combined - all-runs'!$B:$B, B10,'Data Combined - all-runs'!$C:$C, C10, 'Data Combined - all-runs'!$D:$D, D10, 'Data Combined - all-runs'!$E:$E, E10) -> 20 | O10: =AVERAGEIFS('Data Combined - all-runs'!$O:$O, 'Data Combined - all-runs'!$A:$A, A10,'Data Combined - all-runs'!$B:$B, B10,'Data Combined - all-runs'!$C:$C, C10, 'Data Combined - all-runs'!$D:$D, D10, 'Data Combined - all-runs'!$E:$E, E10) -> 1980 | P10: =AVERAGEIFS('Data Combined - all-runs'!$P:$P, 'Data Combined - all-runs'!$A:$A, A10,'Data Combined - all-runs'!$B:$B, B10,'Data Combined - all-runs'!$C:$C, C10, 'Data Combined - all-runs'!$D:$D, D10, 'Data Combined - all-runs'!$E:$E, E10) -> 10.10101 | Q10: =AVERAGEIFS('Data Combined - all-runs'!$Q:$Q, 'Data Combined - all-runs'!$A:$A, A10,'Data Combined - all-runs'!$B:$B, B10,'Data Combined - all-runs'!$C:$C, C10, 'Data Combined - all-runs'!$D:$D, D10, 'Data Combined - all-runs'!$E:$E, E10) -> 753.53535 | R10: =AVERAGEIFS('Data Combined - all-runs'!$R:$R, 'Data Combined - all-runs'!$A:$A, A10,'Data Combined - all-runs'!$B:$B, B10,'Data Combined - all-runs'!$C:$C, C10, 'Data Combined - all-runs'!$D:$D, D10, 'Data Combined - all-runs'!$E:$E, E10) -> 74.6 | S10: =AVERAGEIFS('Data Combined - all-runs'!$S:$S, 'Data Combined - all-runs'!$A:$A, A10,'Data Combined - all-runs'!$B:$B, B10,'Data Combined - all-runs'!$C:$C, C10, 'Data Combined - all-runs'!$D:$D, D10, 'Data Combined - all-runs'!$E:$E, E10) -> 0.23458445 | T10: =AVERAGEIFS('Data Combined - all-runs'!$T:$T, 'Data Combined - all-runs'!$A:$A, A10,'Data Combined - all-runs'!$B:$B, B10,'Data Combined - all-runs'!$C:$C, C10, 'Data Combined - all-runs'!$D:$D, D10, 'Data Combined - all-runs'!$E:$E, E10) -> 0 | U10: =AND( ISNUMBER($H10), SUMPRODUCT( ($A$2:$A$433=$A10)* ($B$2:$B$433=$B10)* ($C$2:$C$433=IF($C10="Json","Natural","Json"))* ($D$2:$D$433=$D10)* ($E$2:$E$433=$E10)* ISNUMBER($H$2:$H$433) )>0 ) -> FALSE | V10: =AND( ISNUMBER($H10), OR($A10="Calls",$A10="Battery + Shelf"), SUMPRODUCT( ($A$2:$A$433=IF($A10="Calls","Battery + Shelf","Calls"))* ($B$2:$B$433=$B10)* ($C$2:$C$433=$C10)* ($D$2:$D$433=$D10)* ($E$2:$E$433=$E10)* ISNUMBER($H$2:$H$433) )>0 ) -> FALSE | W10: =AND( ISNUMBER($H10), OR( $A10="Calls", $A10="Battery + Shelf", $A10="Battery" ), SUMPRODUCT( ($A$2:$A$433="Calls")* ($B$2:$B$433=$B10)* ($C$2:$C$433=$C10)* ($D$2:$D$433=$D10)* ($E$2:$E$433=$E10)* ISNUMBER($H$2:$H$433) )>0, SUMPRODUCT( ($A$2:$A$433="Battery + Shelf")* ($B$2:$B$433=$B10)* ($C$2:$C$433=$C10)* ($D$2:$D$433=$D10)* ($E$2:$E$433=$E10)* ISNUMBER($H$2:$H$433) )>0, SUMPRODUCT( ($A$2:$A$433="Battery")* ($B$2:$B$433=$B10)* ($C$2:$C$433=$C10)* ($D$2:$D$433=$D10)* ($E$2:$E$433=$E10)* ISNUMBER($H$2:$H$433) )>0 ) -> TRUE
A11: Battery | B11: Centralized | C11: Natural | D11: llama 3b (3.2) | E11: small_picker_heavy_2v4 | H11: =AVERAGEIFS('Data Combined - all-runs'!$H:$H, 'Data Combined - all-runs'!$A:$A, A11,'Data Combined - all-runs'!$B:$B, B11,'Data Combined - all-runs'!$C:$C, C11, 'Data Combined - all-runs'!$D:$D, D11, 'Data Combined - all-runs'!$E:$E, E11) -> 1912 | I11: =AVERAGEIFS('Data Combined - all-runs'!$I:$I, 'Data Combined - all-runs'!$A:$A, A11,'Data Combined - all-runs'!$B:$B, B11,'Data Combined - all-runs'!$C:$C, C11, 'Data Combined - all-runs'!$D:$D, D11, 'Data Combined - all-runs'!$E:$E, E11) -> 0 | J11: =AVERAGEIFS('Data Combined - all-runs'!$J:$J, 'Data Combined - all-runs'!$A:$A, A11,'Data Combined - all-runs'!$B:$B, B11,'Data Combined - all-runs'!$C:$C, C11, 'Data Combined - all-runs'!$D:$D, D11, 'Data Combined - all-runs'!$E:$E, E11) -> 889 | K11: =AVERAGEIFS('Data Combined - all-runs'!$K:$K, 'Data Combined - all-runs'!$A:$A, A11,'Data Combined - all-runs'!$B:$B, B11,'Data Combined - all-runs'!$C:$C, C11, 'Data Combined - all-runs'!$D:$D, D11, 'Data Combined - all-runs'!$E:$E, E11) -> 0.20142563 | L11: =AVERAGEIFS('Data Combined - all-runs'!$L:$L, 'Data Combined - all-runs'!$A:$A, A11,'Data Combined - all-runs'!$B:$B, B11,'Data Combined - all-runs'!$C:$C, C11, 'Data Combined - all-runs'!$D:$D, D11, 'Data Combined - all-runs'!$E:$E, E11) -> 15936.154 | M11: =AVERAGEIFS('Data Combined - all-runs'!$M:$M, 'Data Combined - all-runs'!$A:$A, A11,'Data Combined - all-runs'!$B:$B, B11,'Data Combined - all-runs'!$C:$C, C11, 'Data Combined - all-runs'!$D:$D, D11, 'Data Combined - all-runs'!$E:$E, E11) -> 221 | N11: =AVERAGEIFS('Data Combined - all-runs'!$N:$N, 'Data Combined - all-runs'!$A:$A, A11,'Data Combined - all-runs'!$B:$B, B11,'Data Combined - all-runs'!$C:$C, C11, 'Data Combined - all-runs'!$D:$D, D11, 'Data Combined - all-runs'!$E:$E, E11) -> 8 | O11: =AVERAGEIFS('Data Combined - all-runs'!$O:$O, 'Data Combined - all-runs'!$A:$A, A11,'Data Combined - all-runs'!$B:$B, B11,'Data Combined - all-runs'!$C:$C, C11, 'Data Combined - all-runs'!$D:$D, D11, 'Data Combined - all-runs'!$E:$E, E11) -> 2268 | P11: =AVERAGEIFS('Data Combined - all-runs'!$P:$P, 'Data Combined - all-runs'!$A:$A, A11,'Data Combined - all-runs'!$B:$B, B11,'Data Combined - all-runs'!$C:$C, C11, 'Data Combined - all-runs'!$D:$D, D11, 'Data Combined - all-runs'!$E:$E, E11) -> 3.5273369 | Q11: =AVERAGEIFS('Data Combined - all-runs'!$Q:$Q, 'Data Combined - all-runs'!$A:$A, A11,'Data Combined - all-runs'!$B:$B, B11,'Data Combined - all-runs'!$C:$C, C11, 'Data Combined - all-runs'!$D:$D, D11, 'Data Combined - all-runs'!$E:$E, E11) -> 843.03351 | R11: =AVERAGEIFS('Data Combined - all-runs'!$R:$R, 'Data Combined - all-runs'!$A:$A, A11,'Data Combined - all-runs'!$B:$B, B11,'Data Combined - all-runs'!$C:$C, C11, 'Data Combined - all-runs'!$D:$D, D11, 'Data Combined - all-runs'!$E:$E, E11) -> 239 | S11: =AVERAGEIFS('Data Combined - all-runs'!$S:$S, 'Data Combined - all-runs'!$A:$A, A11,'Data Combined - all-runs'!$B:$B, B11,'Data Combined - all-runs'!$C:$C, C11, 'Data Combined - all-runs'!$D:$D, D11, 'Data Combined - all-runs'!$E:$E, E11) -> 0.46495816 | T11: =AVERAGEIFS('Data Combined - all-runs'!$T:$T, 'Data Combined - all-runs'!$A:$A, A11,'Data Combined - all-runs'!$B:$B, B11,'Data Combined - all-runs'!$C:$C, C11, 'Data Combined - all-runs'!$D:$D, D11, 'Data Combined - all-runs'!$E:$E, E11) -> 0 | U11: =AND( ISNUMBER($H11), SUMPRODUCT( ($A$2:$A$433=$A11)* ($B$2:$B$433=$B11)* ($C$2:$C$433=IF($C11="Json","Natural","Json"))* ($D$2:$D$433=$D11)* ($E$2:$E$433=$E11)* ISNUMBER($H$2:$H$433) )>0 ) -> FALSE | V11: =AND( ISNUMBER($H11), OR($A11="Calls",$A11="Battery + Shelf"), SUMPRODUCT( ($A$2:$A$433=IF($A11="Calls","Battery + Shelf","Calls"))* ($B$2:$B$433=$B11)* ($C$2:$C$433=$C11)* ($D$2:$D$433=$D11)* ($E$2:$E$433=$E11)* ISNUMBER($H$2:$H$433) )>0 ) -> FALSE | W11: =AND( ISNUMBER($H11), OR( $A11="Calls", $A11="Battery + Shelf", $A11="Battery" ), SUMPRODUCT( ($A$2:$A$433="Calls")* ($B$2:$B$433=$B11)* ($C$2:$C$433=$C11)* ($D$2:$D$433=$D11)* ($E$2:$E$433=$E11)* ISNUMBER($H$2:$H$433) )>0, SUMPRODUCT( ($A$2:$A$433="Battery + Shelf")* ($B$2:$B$433=$B11)* ($C$2:$C$433=$C11)* ($D$2:$D$433=$D11)* ($E$2:$E$433=$E11)* ISNUMBER($H$2:$H$433) )>0, SUMPRODUCT( ($A$2:$A$433="Battery")* ($B$2:$B$433=$B11)* ($C$2:$C$433=$C11)* ($D$2:$D$433=$D11)* ($E$2:$E$433=$E11)* ISNUMBER($H$2:$H$433) )>0 ) -> TRUE
A12: Battery | B12: Centralized | C12: Natural | D12: llama 3b (3.2) | E12: medium_balanced_4v4 | H12: =AVERAGEIFS('Data Combined - all-runs'!$H:$H, 'Data Combined - all-runs'!$A:$A, A12,'Data Combined - all-runs'!$B:$B, B12,'Data Combined - all-runs'!$C:$C, C12, 'Data Combined - all-runs'!$D:$D, D12, 'Data Combined - all-runs'!$E:$E, E12) -> 1816 | I12: =AVERAGEIFS('Data Combined - all-runs'!$I:$I, 'Data Combined - all-runs'!$A:$A, A12,'Data Combined - all-runs'!$B:$B, B12,'Data Combined - all-runs'!$C:$C, C12, 'Data Combined - all-runs'!$D:$D, D12, 'Data Combined - all-runs'!$E:$E, E12) -> 0 | J12: =AVERAGEIFS('Data Combined - all-runs'!$J:$J, 'Data Combined - all-runs'!$A:$A, A12,'Data Combined - all-runs'!$B:$B, B12,'Data Combined - all-runs'!$C:$C, C12, 'Data Combined - all-runs'!$D:$D, D12, 'Data Combined - all-runs'!$E:$E, E12) -> 828 | K12: =AVERAGEIFS('Data Combined - all-runs'!$K:$K, 'Data Combined - all-runs'!$A:$A, A12,'Data Combined - all-runs'!$B:$B, B12,'Data Combined - all-runs'!$C:$C, C12, 'Data Combined - all-runs'!$D:$D, D12, 'Data Combined - all-runs'!$E:$E, E12) -> 0.16623651 | L12: =AVERAGEIFS('Data Combined - all-runs'!$L:$L, 'Data Combined - all-runs'!$A:$A, A12,'Data Combined - all-runs'!$B:$B, B12,'Data Combined - all-runs'!$C:$C, C12, 'Data Combined - all-runs'!$D:$D, D12, 'Data Combined - all-runs'!$E:$E, E12) -> 15569.772 | M12: =AVERAGEIFS('Data Combined - all-runs'!$M:$M, 'Data Combined - all-runs'!$A:$A, A12,'Data Combined - all-runs'!$B:$B, B12,'Data Combined - all-runs'!$C:$C, C12, 'Data Combined - all-runs'!$D:$D, D12, 'Data Combined - all-runs'!$E:$E, E12) -> 68 | N12: =AVERAGEIFS('Data Combined - all-runs'!$N:$N, 'Data Combined - all-runs'!$A:$A, A12,'Data Combined - all-runs'!$B:$B, B12,'Data Combined - all-runs'!$C:$C, C12, 'Data Combined - all-runs'!$D:$D, D12, 'Data Combined - all-runs'!$E:$E, E12) -> 20 | O12: =AVERAGEIFS('Data Combined - all-runs'!$O:$O, 'Data Combined - all-runs'!$A:$A, A12,'Data Combined - all-runs'!$B:$B, B12,'Data Combined - all-runs'!$C:$C, C12, 'Data Combined - all-runs'!$D:$D, D12, 'Data Combined - all-runs'!$E:$E, E12) -> 2131 | P12: =AVERAGEIFS('Data Combined - all-runs'!$P:$P, 'Data Combined - all-runs'!$A:$A, A12,'Data Combined - all-runs'!$B:$B, B12,'Data Combined - all-runs'!$C:$C, C12, 'Data Combined - all-runs'!$D:$D, D12, 'Data Combined - all-runs'!$E:$E, E12) -> 9.3852651 | Q12: =AVERAGEIFS('Data Combined - all-runs'!$Q:$Q, 'Data Combined - all-runs'!$A:$A, A12,'Data Combined - all-runs'!$B:$B, B12,'Data Combined - all-runs'!$C:$C, C12, 'Data Combined - all-runs'!$D:$D, D12, 'Data Combined - all-runs'!$E:$E, E12) -> 852.18207 | R12: =AVERAGEIFS('Data Combined - all-runs'!$R:$R, 'Data Combined - all-runs'!$A:$A, A12,'Data Combined - all-runs'!$B:$B, B12,'Data Combined - all-runs'!$C:$C, C12, 'Data Combined - all-runs'!$D:$D, D12, 'Data Combined - all-runs'!$E:$E, E12) -> 90.8 | S12: =AVERAGEIFS('Data Combined - all-runs'!$S:$S, 'Data Combined - all-runs'!$A:$A, A12,'Data Combined - all-runs'!$B:$B, B12,'Data Combined - all-runs'!$C:$C, C12, 'Data Combined - all-runs'!$D:$D, D12, 'Data Combined - all-runs'!$E:$E, E12) -> 0.45594714 | T12: =AVERAGEIFS('Data Combined - all-runs'!$T:$T, 'Data Combined - all-runs'!$A:$A, A12,'Data Combined - all-runs'!$B:$B, B12,'Data Combined - all-runs'!$C:$C, C12, 'Data Combined - all-runs'!$D:$D, D12, 'Data Combined - all-runs'!$E:$E, E12) -> 0 | U12: =AND( ISNUMBER($H12), SUMPRODUCT( ($A$2:$A$433=$A12)* ($B$2:$B$433=$B12)* ($C$2:$C$433=IF($C12="Json","Natural","Json"))* ($D$2:$D$433=$D12)* ($E$2:$E$433=$E12)* ISNUMBER($H$2:$H$433) )>0 ) -> FALSE | V12: =AND( ISNUMBER($H12), OR($A12="Calls",$A12="Battery + Shelf"), SUMPRODUCT( ($A$2:$A$433=IF($A12="Calls","Battery + Shelf","Calls"))* ($B$2:$B$433=$B12)* ($C$2:$C$433=$C12)* ($D$2:$D$433=$D12)* ($E$2:$E$433=$E12)* ISNUMBER($H$2:$H$433) )>0 ) -> FALSE | W12: =AND( ISNUMBER($H12), OR( $A12="Calls", $A12="Battery + Shelf", $A12="Battery" ), SUMPRODUCT( ($A$2:$A$433="Calls")* ($B$2:$B$433=$B12)* ($C$2:$C$433=$C12)* ($D$2:$D$433=$D12)* ($E$2:$E$433=$E12)* ISNUMBER($H$2:$H$433) )>0, SUMPRODUCT( ($A$2:$A$433="Battery + Shelf")* ($B$2:$B$433=$B12)* ($C$2:$C$433=$C12)* ($D$2:$D$433=$D12)* ($E$2:$E$433=$E12)* ISNUMBER($H$2:$H$433) )>0, SUMPRODUCT( ($A$2:$A$433="Battery")* ($B$2:$B$433=$B12)* ($C$2:$C$433=$C12)* ($D$2:$D$433=$D12)* ($E$2:$E$433=$E12)* ISNUMBER($H$2:$H$433) )>0 ) -> TRUE
A13: Battery | B13: Centralized | C13: Natural | D13: llama 3b (3.2) | E13: medium_agv_heavy_6v2 | H13: =AVERAGEIFS('Data Combined - all-runs'!$H:$H, 'Data Combined - all-runs'!$A:$A, A13,'Data Combined - all-runs'!$B:$B, B13,'Data Combined - all-runs'!$C:$C, C13, 'Data Combined - all-runs'!$D:$D, D13, 'Data Combined - all-runs'!$E:$E, E13) -> 1477 | I13: =AVERAGEIFS('Data Combined - all-runs'!$I:$I, 'Data Combined - all-runs'!$A:$A, A13,'Data Combined - all-runs'!$B:$B, B13,'Data Combined - all-runs'!$C:$C, C13, 'Data Combined - all-runs'!$D:$D, D13, 'Data Combined - all-runs'!$E:$E, E13) -> 0 | J13: =AVERAGEIFS('Data Combined - all-runs'!$J:$J, 'Data Combined - all-runs'!$A:$A, A13,'Data Combined - all-runs'!$B:$B, B13,'Data Combined - all-runs'!$C:$C, C13, 'Data Combined - all-runs'!$D:$D, D13, 'Data Combined - all-runs'!$E:$E, E13) -> 446 | K13: =AVERAGEIFS('Data Combined - all-runs'!$K:$K, 'Data Combined - all-runs'!$A:$A, A13,'Data Combined - all-runs'!$B:$B, B13,'Data Combined - all-runs'!$C:$C, C13, 'Data Combined - all-runs'!$D:$D, D13, 'Data Combined - all-runs'!$E:$E, E13) -> 0.14384867 | L13: =AVERAGEIFS('Data Combined - all-runs'!$L:$L, 'Data Combined - all-runs'!$A:$A, A13,'Data Combined - all-runs'!$B:$B, B13,'Data Combined - all-runs'!$C:$C, C13, 'Data Combined - all-runs'!$D:$D, D13, 'Data Combined - all-runs'!$E:$E, E13) -> 11086.583 | M13: =AVERAGEIFS('Data Combined - all-runs'!$M:$M, 'Data Combined - all-runs'!$A:$A, A13,'Data Combined - all-runs'!$B:$B, B13,'Data Combined - all-runs'!$C:$C, C13, 'Data Combined - all-runs'!$D:$D, D13, 'Data Combined - all-runs'!$E:$E, E13) -> 38 | N13: =AVERAGEIFS('Data Combined - all-runs'!$N:$N, 'Data Combined - all-runs'!$A:$A, A13,'Data Combined - all-runs'!$B:$B, B13,'Data Combined - all-runs'!$C:$C, C13, 'Data Combined - all-runs'!$D:$D, D13, 'Data Combined - all-runs'!$E:$E, E13) -> 20 | O13: =AVERAGEIFS('Data Combined - all-runs'!$O:$O, 'Data Combined - all-runs'!$A:$A, A13,'Data Combined - all-runs'!$B:$B, B13,'Data Combined - all-runs'!$C:$C, C13, 'Data Combined - all-runs'!$D:$D, D13, 'Data Combined - all-runs'!$E:$E, E13) -> 1837 | P13: =AVERAGEIFS('Data Combined - all-runs'!$P:$P, 'Data Combined - all-runs'!$A:$A, A13,'Data Combined - all-runs'!$B:$B, B13,'Data Combined - all-runs'!$C:$C, C13, 'Data Combined - all-runs'!$D:$D, D13, 'Data Combined - all-runs'!$E:$E, E13) -> 10.887316 | Q13: =AVERAGEIFS('Data Combined - all-runs'!$Q:$Q, 'Data Combined - all-runs'!$A:$A, A13,'Data Combined - all-runs'!$B:$B, B13,'Data Combined - all-runs'!$C:$C, C13, 'Data Combined - all-runs'!$D:$D, D13, 'Data Combined - all-runs'!$E:$E, E13) -> 804.02831 | R13: =AVERAGEIFS('Data Combined - all-runs'!$R:$R, 'Data Combined - all-runs'!$A:$A, A13,'Data Combined - all-runs'!$B:$B, B13,'Data Combined - all-runs'!$C:$C, C13, 'Data Combined - all-runs'!$D:$D, D13, 'Data Combined - all-runs'!$E:$E, E13) -> 73.85 | S13: =AVERAGEIFS('Data Combined - all-runs'!$S:$S, 'Data Combined - all-runs'!$A:$A, A13,'Data Combined - all-runs'!$B:$B, B13,'Data Combined - all-runs'!$C:$C, C13, 'Data Combined - all-runs'!$D:$D, D13, 'Data Combined - all-runs'!$E:$E, E13) -> 0.30196344 | T13: =AVERAGEIFS('Data Combined - all-runs'!$T:$T, 'Data Combined - all-runs'!$A:$A, A13,'Data Combined - all-runs'!$B:$B, B13,'Data Combined - all-runs'!$C:$C, C13, 'Data Combined - all-runs'!$D:$D, D13, 'Data Combined - all-runs'!$E:$E, E13) -> 0 | U13: =AND( ISNUMBER($H13), SUMPRODUCT( ($A$2:$A$433=$A13)* ($B$2:$B$433=$B13)* ($C$2:$C$433=IF($C13="Json","Natural","Json"))* ($D$2:$D$433=$D13)* ($E$2:$E$433=$E13)* ISNUMBER($H$2:$H$433) )>0 ) -> FALSE | V13: =AND( ISNUMBER($H13), OR($A13="Calls",$A13="Battery + Shelf"), SUMPRODUCT( ($A$2:$A$433=IF($A13="Calls","Battery + Shelf","Calls"))* ($B$2:$B$433=$B13)* ($C$2:$C$433=$C13)* ($D$2:$D$433=$D13)* ($E$2:$E$433=$E13)* ISNUMBER($H$2:$H$433) )>0 ) -> FALSE | W13: =AND( ISNUMBER($H13), OR( $A13="Calls", $A13="Battery + Shelf", $A13="Battery" ), SUMPRODUCT( ($A$2:$A$433="Calls")* ($B$2:$B$433=$B13)* ($C$2:$C$433=$C13)* ($D$2:$D$433=$D13)* ($E$2:$E$433=$E13)* ISNUMBER($H$2:$H$433) )>0, SUMPRODUCT( ($A$2:$A$433="Battery + Shelf")* ($B$2:$B$433=$B13)* ($C$2:$C$433=$C13)* ($D$2:$D$433=$D13)* ($E$2:$E$433=$E13)* ISNUMBER($H$2:$H$433) )>0, SUMPRODUCT( ($A$2:$A$433="Battery")* ($B$2:$B$433=$B13)* ($C$2:$C$433=$C13)* ($D$2:$D$433=$D13)* ($E$2:$E$433=$E13)* ISNUMBER($H$2:$H$433) )>0 ) -> TRUE
... A433: Calls | B433: Shared | C433: Json | D433: qwen 14b (2.5) | E433: medium_agv_heavy_6v2 | H433: =AVERAGEIFS('Data Combined - all-runs'!$H:$H, 'Data Combined - all-runs'!$A:$A, A433,'Data Combined - all-runs'!$B:$B, B433,'Data Combined - all-runs'!$C:$C, C433, 'Data Combined - all-runs'!$D:$D, D433, 'Data Combined - all-runs'!$E:$E, E433) -> 2153 | I433: =AVERAGEIFS('Data Combined - all-runs'!$I:$I, 'Data Combined - all-runs'!$A:$A, A433,'Data Combined - all-runs'!$B:$B, B433,'Data Combined - all-runs'!$C:$C, C433, 'Data Combined - all-runs'!$D:$D, D433, 'Data Combined - all-runs'!$E:$E, E433) -> 0 | J433: =AVERAGEIFS('Data Combined - all-runs'!$J:$J, 'Data Combined - all-runs'!$A:$A, A433,'Data Combined - all-runs'!$B:$B, B433,'Data Combined - all-runs'!$C:$C, C433, 'Data Combined - all-runs'!$D:$D, D433, 'Data Combined - all-runs'!$E:$E, E433) -> 2 | K433: =AVERAGEIFS('Data Combined - all-runs'!$K:$K, 'Data Combined - all-runs'!$A:$A, A433,'Data Combined - all-runs'!$B:$B, B433,'Data Combined - all-runs'!$C:$C, C433, 'Data Combined - all-runs'!$D:$D, D433, 'Data Combined - all-runs'!$E:$E, E433) -> 0.22 | L433: =AVERAGEIFS('Data Combined - all-runs'!$L:$L, 'Data Combined - all-runs'!$A:$A, A433,'Data Combined - all-runs'!$B:$B, B433,'Data Combined - all-runs'!$C:$C, C433, 'Data Combined - all-runs'!$D:$D, D433, 'Data Combined - all-runs'!$E:$E, E433) -> 8127.0559 | M433: =AVERAGEIFS('Data Combined - all-runs'!$M:$M, 'Data Combined - all-runs'!$A:$A, A433,'Data Combined - all-runs'!$B:$B, B433,'Data Combined - all-runs'!$C:$C, C433, 'Data Combined - all-runs'!$D:$D, D433, 'Data Combined - all-runs'!$E:$E, E433) -> #DIV/0! | N433: =AVERAGEIFS('Data Combined - all-runs'!$N:$N, 'Data Combined - all-runs'!$A:$A, A433,'Data Combined - all-runs'!$B:$B, B433,'Data Combined - all-runs'!$C:$C, C433, 'Data Combined - all-runs'!$D:$D, D433, 'Data Combined - all-runs'!$E:$E, E433) -> 0 | O433: =AVERAGEIFS('Data Combined - all-runs'!$O:$O, 'Data Combined - all-runs'!$A:$A, A433,'Data Combined - all-runs'!$B:$B, B433,'Data Combined - all-runs'!$C:$C, C433, 'Data Combined - all-runs'!$D:$D, D433, 'Data Combined - all-runs'!$E:$E, E433) -> 500 | P433: =AVERAGEIFS('Data Combined - all-runs'!$P:$P, 'Data Combined - all-runs'!$A:$A, A433,'Data Combined - all-runs'!$B:$B, B433,'Data Combined - all-runs'!$C:$C, C433, 'Data Combined - all-runs'!$D:$D, D433, 'Data Combined - all-runs'!$E:$E, E433) -> 0 | Q433: =AVERAGEIFS('Data Combined - all-runs'!$Q:$Q, 'Data Combined - all-runs'!$A:$A, A433,'Data Combined - all-runs'!$B:$B, B433,'Data Combined - all-runs'!$C:$C, C433, 'Data Combined - all-runs'!$D:$D, D433, 'Data Combined - all-runs'!$E:$E, E433) -> 4306 | R433: =AVERAGEIFS('Data Combined - all-runs'!$R:$R, 'Data Combined - all-runs'!$A:$A, A433,'Data Combined - all-runs'!$B:$B, B433,'Data Combined - all-runs'!$C:$C, C433, 'Data Combined - all-runs'!$D:$D, D433, 'Data Combined - all-runs'!$E:$E, E433) -> #DIV/0! | S433: =AVERAGEIFS('Data Combined - all-runs'!$S:$S, 'Data Combined - all-runs'!$A:$A, A433,'Data Combined - all-runs'!$B:$B, B433,'Data Combined - all-runs'!$C:$C, C433, 'Data Combined - all-runs'!$D:$D, D433, 'Data Combined - all-runs'!$E:$E, E433) -> 0.00092893637 | T433: =AVERAGEIFS('Data Combined - all-runs'!$T:$T, 'Data Combined - all-runs'!$A:$A, A433,'Data Combined - all-runs'!$B:$B, B433,'Data Combined - all-runs'!$C:$C, C433, 'Data Combined - all-runs'!$D:$D, D433, 'Data Combined - all-runs'!$E:$E, E433) -> 0 | U433: =AND( ISNUMBER($H433), SUMPRODUCT( ($A$2:$A$433=$A433)* ($B$2:$B$433=$B433)* ($C$2:$C$433=IF($C433="Json","Natural","Json"))* ($D$2:$D$433=$D433)* ($E$2:$E$433=$E433)* ISNUMBER($H$2:$H$433) )>0 ) -> TRUE | V433: =AND( ISNUMBER($H433), OR($A433="Calls",$A433="Battery + Shelf"), SUMPRODUCT( ($A$2:$A$433=IF($A433="Calls","Battery + Shelf","Calls"))* ($B$2:$B$433=$B433)* ($C$2:$C$433=$C433)* ($D$2:$D$433=$D433)* ($E$2:$E$433=$E433)* ISNUMBER($H$2:$H$433) )>0 ) -> TRUE | W433: =AND( ISNUMBER($H433), OR( $A433="Calls", $A433="Battery + Shelf", $A433="Battery" ), SUMPRODUCT( ($A$2:$A$433="Calls")* ($B$2:$B$433=$B433)* ($C$2:$C$433=$C433)* ($D$2:$D$433=$D433)* ($E$2:$E$433=$E433)* ISNUMBER($H$2:$H$433) )>0, SUMPRODUCT( ($A$2:$A$433="Battery + Shelf")* ($B$2:$B$433=$B433)* ($C$2:$C$433=$C433)* ($D$2:$D$433=$D433)* ($E$2:$E$433=$E433)* ISNUMBER($H$2:$H$433) )>0, SUMPRODUCT( ($A$2:$A$433="Battery")* ($B$2:$B$433=$B433)* ($C$2:$C$433=$C433)* ($D$2:$D$433=$D433)* ($E$2:$E$433=$E433)* ISNUMBER($H$2:$H$433) )>0 ) -> FALSE

Sheet Data Combined - all-runs
A1: Objective | B1: Arch | C1: Prompt | D1: Model | E1: Scenario | F1: Seed | G1: Run | H1: llm_calls | I1: json_generation_failures | J1: llm_missing_or_invalid_actions | K1: charging_station_utilization_rate | L1: elapsed_seconds | M1: steps to first delivery | N1: total deliveries | O1: total steps | P1: deliveries_per_1000_steps | Q1: llm_calls_per_1000_steps | R1: llm_calls_per_delivery | S1: invalid_action_rate | T1: json_failure_rate | U1: summary_json_path
A2: Calls | B2: Centralized | C2: Json | D2: llama 1b (3.2) | E2: tiny_balanced_1v1 | F2: 0 | G2: valid_session1/session1 | H2: 478 | I2: 1 | J2: 2 | K2: 0 | L2: 3012.4304 | N2: 0 | O2: 500 | P2: 0 | Q2: 956 | S2: 0.0041841004 | T2: 0.0020920502 | U2: Battery-TA-RWARE/results/calls/centralized/json/valid_session1/llama3.2_1b/session1/tiny_balanced_1v1/json/summary.json
A3: Calls | B3: Centralized | C3: Json | D3: llama 1b (3.2) | E3: small_balanced_2v2 | F3: 0 | G3: session_20260422_155053 | H3: 491 | I3: 0 | J3: 344 | K3: 0 | L3: 2221.9595 | N3: 0 | O3: 500 | P3: 0 | Q3: 982 | S3: 0.700611 | T3: 0 | U3: Battery-TA-RWARE/results/calls/centralized/json/session_20260422_155053/llama3.2_1b/small_balanced_2v2/json/summary.json
A4: Calls | B4: Centralized | C4: Json | D4: llama 1b (3.2) | E4: small_balanced_2v2 | F4: 0 | G4: session_20260422_220055 | H4: 491 | I4: 0 | J4: 0 | K4: 0 | L4: 2611.1534 | N4: 0 | O4: 500 | P4: 0 | Q4: 982 | S4: 0 | T4: 0 | U4: Battery-TA-RWARE/results/calls/centralized/json/session_20260422_220055/llama3.2_1b/small_balanced_2v2/json/summary.json
A5: Calls | B5: Centralized | C5: Json | D5: llama 1b (3.2) | E5: small_balanced_2v2 | F5: 0 | G5: valid_session1/session1 | H5: 491 | I5: 0 | J5: 0 | K5: 0 | L5: 2611.1534 | N5: 0 | O5: 500 | P5: 0 | Q5: 982 | S5: 0 | T5: 0 | U5: Battery-TA-RWARE/results/calls/centralized/json/valid_session1/llama3.2_1b/session1/small_balanced_2v2/json/summary.json
A6: Calls | B6: Centralized | C6: Json | D6: llama 1b (3.2) | E6: small_agv_heavy_4v2 | F6: 0 | G6: session_20260422_083558 | H6: 492 | I6: 0 | J6: 5 | K6: 0 | L6: 2684.8153 | N6: 0 | O6: 500 | P6: 0 | Q6: 984 | S6: 0.010162602 | T6: 0 | U6: Battery-TA-RWARE/results/calls/centralized/json/session_20260422_083558/llama3.2_1b/small_agv_heavy_4v2/json/summary.json
A7: Calls | B7: Centralized | C7: Json | D7: llama 1b (3.2) | E7: small_agv_heavy_4v2 | F7: 0 | G7: session_20260422_155053 | H7: 146 | I7: 0 | J7: 234 | K7: 0 | L7: 6942.6538 | N7: 0 | O7: 500 | P7: 0 | Q7: 292 | S7: 1.6027397 | T7: 0 | U7: Battery-TA-RWARE/results/calls/centralized/json/session_20260422_155053/llama3.2_1b/small_agv_heavy_4v2/json/summary.json
